<mujoco model="unnamed_model">
  <compiler angle="radian" autolimits="true"/>
  <option impratio="10" integrator="implicitfast"/>
  <size nkey="1"/>
  <statistic meansize="0.0887356" extent="1.127" center="-0.102704 0.3635 0.286603"/>
  <default class="main">
    <default class="/"/>
    <default class="ur5e/">
      <default class="ur5e/ur5e">
        <material shininess="0.25"/>
        <joint range="-6.28319 6.28319" armature="0.1"/>
        <site size="0.001 0.005 0.005" group="4" rgba="0.5 0.5 0.5 0.3"/>
        <general ctrlrange="-6.2831 6.2831" forcerange="-150 150" biastype="affine" gainprm="2000 0 0 0 0 0 0 0 0 0" biasprm="0 -2000 -400 0 0 0 0 0 0 0"/>
        <default class="ur5e/size3">
          <default class="ur5e/size3_limited">
            <joint range="-3.1415 3.1415"/>
            <general ctrlrange="-3.1415 3.1415"/>
          </default>
        </default>
        <default class="ur5e/size1">
          <general forcerange="-28 28" gainprm="500 0 0 0 0 0 0 0 0 0" biasprm="0 -500 -100 0 0 0 0 0 0 0"/>
        </default>
        <default class="ur5e/visual">
          <geom type="mesh" contype="0" conaffinity="0" group="2"/>
        </default>
        <default class="ur5e/collision">
          <geom type="capsule" group="3"/>
          <default class="ur5e/eef_collision">
            <geom type="cylinder"/>
          </default>
        </default>
      </default>
    </default>
    <default class="ur5e/robotiq_2f85/">
      <default class="ur5e/robotiq_2f85/2f85">
        <mesh scale="0.001 0.001 0.001"/>
        <general biastype="affine"/>
        <default class="ur5e/robotiq_2f85/driver">
          <joint solreflimit="0.005 1" solimplimit="0.95 0.99 0.001 0.5 2" range="0 0.8" armature="0.005" damping="0.1"/>
        </default>
        <default class="ur5e/robotiq_2f85/follower">
          <joint solreflimit="0.005 1" solimplimit="0.95 0.99 0.001 0.5 2" range="-0.872664 0.872664"/>
        </default>
        <default class="ur5e/robotiq_2f85/spring_link">
          <joint springref="2.62" stiffness="0.05" range="-0.296706 0.8" damping="0.00125"/>
        </default>
        <default class="ur5e/robotiq_2f85/coupler">
          <joint solreflimit="0.005 1" solimplimit="0.95 0.99 0.001 0.5 2" range="-1.57 0"/>
        </default>
        <default class="ur5e/robotiq_2f85/visual">
          <geom type="mesh" contype="0" conaffinity="0" group="2"/>
        </default>
        <default class="ur5e/robotiq_2f85/collision">
          <geom type="mesh" group="3"/>
          <default class="ur5e/robotiq_2f85/pad_box1">
            <geom size="0.011 0.004 0.009375" type="box" priority="1" friction="0.7 0.005 0.0001" solref="0.004 1" solimp="0.95 0.99 0.001 0.5 2" rgba="0.55 0.55 0.55 1"/>
          </default>
          <default class="ur5e/robotiq_2f85/pad_box2">
            <geom size="0.011 0.004 0.009375" type="box" priority="1" friction="0.6 0.005 0.0001" solref="0.004 1" solimp="0.95 0.99 0.001 0.5 2" rgba="0.45 0.45 0.45 1"/>
          </default>
        </default>
      </default>
    </default>
  </default>
  <asset>
    <material name="ur5e/black" class="ur5e/ur5e" rgba="0.033 0.033 0.033 1"/>
    <material name="ur5e/jointgray" class="ur5e/ur5e" rgba="0.278 0.278 0.278 1"/>
    <material name="ur5e/linkgray" class="ur5e/ur5e" rgba="0.82 0.82 0.82 1"/>
    <material name="ur5e/urblue" class="ur5e/ur5e" rgba="0.49 0.678 0.8 1"/>
    <material name="ur5e/robotiq_2f85/metal" class="ur5e/robotiq_2f85/" rgba="0.58 0.58 0.58 1"/>
    <material name="ur5e/robotiq_2f85/silicone" class="ur5e/robotiq_2f85/" rgba="0.1882 0.1882 0.1882 1"/>
    <material name="ur5e/robotiq_2f85/gray" class="ur5e/robotiq_2f85/" rgba="0.4627 0.4627 0.4627 1"/>
    <material name="ur5e/robotiq_2f85/black" class="ur5e/robotiq_2f85/" rgba="0.149 0.149 0.149 1"/>
    <mesh name="ur5e/base_0" class="ur5e/" file="base_0-d5328a99917358d9aa384f12743fe73698461d1c.obj"/>
    <mesh name="ur5e/base_1" class="ur5e/" file="base_1-d1c667ae5f87b9c900fdeadad850205153846396.obj"/>
    <mesh name="ur5e/shoulder_0" class="ur5e/" file="shoulder_0-89051b80580d45ef39cb220bf068742b01770552.obj"/>
    <mesh name="ur5e/shoulder_1" class="ur5e/" file="shoulder_1-50ba15e82459989cf7f17cba7b1aafbca2781206.obj"/>
    <mesh name="ur5e/shoulder_2" class="ur5e/" file="shoulder_2-29ad171bec79e2912abb81d250aaf5ff9a67bc60.obj"/>
    <mesh name="ur5e/upperarm_0" class="ur5e/" file="upperarm_0-16bfdf8d1b19d35ef0adbc4cf29ab0c7edb62dcf.obj"/>
    <mesh name="ur5e/upperarm_1" class="ur5e/" file="upperarm_1-c53724435bec35e1b608145457af767b038f4fd1.obj"/>
    <mesh name="ur5e/upperarm_2" class="ur5e/" file="upperarm_2-199e0d0c1baa55a078742ed298800ff26d072c09.obj"/>
    <mesh name="ur5e/upperarm_3" class="ur5e/" file="upperarm_3-62f2bba935d9ab94800a49bcb6ede7b0fa9dd071.obj"/>
    <mesh name="ur5e/forearm_0" class="ur5e/" file="forearm_0-7994229075bdd0e4a5c860ca174278ee8eda8229.obj"/>
    <mesh name="ur5e/forearm_1" class="ur5e/" file="forearm_1-c72848167eef89e0d9801ddd7da516e7e878776e.obj"/>
    <mesh name="ur5e/forearm_2" class="ur5e/" file="forearm_2-3a33518f421ed893ff9b0d759af07b0e5900e78c.obj"/>
    <mesh name="ur5e/forearm_3" class="ur5e/" file="forearm_3-54cad2556a94cdda04a7cef5c84554a7d9f3ab03.obj"/>
    <mesh name="ur5e/wrist1_0" class="ur5e/" file="wrist1_0-6876ccb9d0084054268dd6aec007e5a61aea6c2d.obj"/>
    <mesh name="ur5e/wrist1_1" class="ur5e/" file="wrist1_1-0f7e6640a9dfb98e58078997f5f82bd433879387.obj"/>
    <mesh name="ur5e/wrist1_2" class="ur5e/" file="wrist1_2-3f6dcae8c736e2c42db3746db7f24ac4516aaca7.obj"/>
    <mesh name="ur5e/wrist2_0" class="ur5e/" file="wrist2_0-fdb3f7bc360f8f37f6be6270c8b507291dc9b01c.obj"/>
    <mesh name="ur5e/wrist2_1" class="ur5e/" file="wrist2_1-258ca475798c530d954723dc29f3d67086ead0d9.obj"/>
    <mesh name="ur5e/wrist2_2" class="ur5e/" file="wrist2_2-c6734971531db7f2f09e746377aa9faccb69b192.obj"/>
    <mesh name="ur5e/wrist3" class="ur5e/" file="wrist3-a1fffb4f599e121fb18be40e087b6fd7fb164e59.obj"/>
    <mesh name="ur5e/robotiq_2f85/base_mount" class="ur5e/robotiq_2f85/2f85" file="base_mount-22e57178defe77afb6bdd333bfae16607f1eb3dd.stl"/>
    <mesh name="ur5e/robotiq_2f85/base" class="ur5e/robotiq_2f85/2f85" file="base-e5dacbcc3971bfdb549ff8c7d38ea873ca7f2933.stl"/>
    <mesh name="ur5e/robotiq_2f85/driver" class="ur5e/robotiq_2f85/2f85" file="driver-97efa43184c575b31ff1f3980641896f51492762.stl"/>
    <mesh name="ur5e/robotiq_2f85/coupler" class="ur5e/robotiq_2f85/2f85" file="coupler-0a4240dc94992944cca6ec9e270ff1658fa86c55.stl"/>
    <mesh name="ur5e/robotiq_2f85/follower" class="ur5e/robotiq_2f85/2f85" file="follower-39e4b8048f1395ee38cb45b37b5fec0e6f2aaec9.stl"/>
    <mesh name="ur5e/robotiq_2f85/pad" class="ur5e/robotiq_2f85/2f85" file="pad-e6a633b2c81740b1f783ec4c6e695c8cc570f09d.stl"/>
    <mesh name="ur5e/robotiq_2f85/silicone_pad" class="ur5e/robotiq_2f85/2f85" file="silicone_pad-c284384f3ca6dcdc24d6188a5d1a2d4c42c412ac.stl"/>
    <mesh name="ur5e/robotiq_2f85/spring_link" class="ur5e/robotiq_2f85/2f85" file="spring_link-8f50234325193b84e9f86b7a63a24560a389c9bf.stl"/>
  </asset>
  <worldbody>
    <geom name="//unnamed_geom_0" class="/" size="2 2 0.1" type="plane" friction="1 0.5 0.5"/>
    <body name="ur5e/">
      <light name="ur5e/spotlight" class="ur5e/" target="ur5e/wrist_2_link" pos="0 -1 2" dir="0 0 -1" mode="targetbodycom"/>
      <body name="ur5e/base" childclass="ur5e/ur5e" quat="0.707107 0 0 0.707107">
        <inertial pos="0 0 0" mass="4" diaginertia="0.00443333 0.00443333 0.0072"/>
        <geom name="ur5e//unnamed_geom_0" class="ur5e/visual" material="ur5e/black" mesh="ur5e/base_0"/>
        <geom name="ur5e//unnamed_geom_1" class="ur5e/visual" material="ur5e/jointgray" mesh="ur5e/base_1"/>
        <body name="ur5e/shoulder_link" pos="0 0 0.163">
          <inertial pos="0 0 0" mass="3.7" diaginertia="0.0102675 0.0102675 0.00666"/>
          <joint name="ur5e/shoulder_pan_joint" class="ur5e/size3" pos="0 0 0" axis="0 0 1"/>
          <geom name="ur5e//unnamed_geom_2" class="ur5e/visual" material="ur5e/urblue" mesh="ur5e/shoulder_0"/>
          <geom name="ur5e//unnamed_geom_3" class="ur5e/visual" material="ur5e/black" mesh="ur5e/shoulder_1"/>
          <geom name="ur5e//unnamed_geom_4" class="ur5e/visual" material="ur5e/jointgray" mesh="ur5e/shoulder_2"/>
          <geom name="ur5e//unnamed_geom_5" class="ur5e/collision" size="0.06 0.06" pos="0 0 -0.04"/>
          <body name="ur5e/upper_arm_link" pos="0 0.138 0" quat="0.707107 0 0.707107 0">
            <inertial pos="0 0 0.2125" mass="8.393" diaginertia="0.133886 0.133886 0.0151074"/>
            <joint name="ur5e/shoulder_lift_joint" class="ur5e/size3" pos="0 0 0" axis="0 1 0"/>
            <geom name="ur5e//unnamed_geom_6" class="ur5e/visual" material="ur5e/linkgray" mesh="ur5e/upperarm_0"/>
            <geom name="ur5e//unnamed_geom_7" class="ur5e/visual" material="ur5e/black" mesh="ur5e/upperarm_1"/>
            <geom name="ur5e//unnamed_geom_8" class="ur5e/visual" material="ur5e/jointgray" mesh="ur5e/upperarm_2"/>
            <geom name="ur5e//unnamed_geom_9" class="ur5e/visual" material="ur5e/urblue" mesh="ur5e/upperarm_3"/>
            <geom name="ur5e//unnamed_geom_10" class="ur5e/collision" size="0.06 0.06" pos="0 -0.04 0" quat="0.707107 0.707107 0 0"/>
            <geom name="ur5e//unnamed_geom_11" class="ur5e/collision" size="0.05 0.2" pos="0 0 0.2"/>
            <body name="ur5e/forearm_link" pos="0 -0.131 0.425">
              <inertial pos="0 0 0.196" mass="2.275" diaginertia="0.0311796 0.0311796 0.004095"/>
              <joint name="ur5e/elbow_joint" class="ur5e/size3_limited" pos="0 0 0" axis="0 1 0"/>
              <geom name="ur5e//unnamed_geom_12" class="ur5e/visual" material="ur5e/urblue" mesh="ur5e/forearm_0"/>
              <geom name="ur5e//unnamed_geom_13" class="ur5e/visual" material="ur5e/linkgray" mesh="ur5e/forearm_1"/>
              <geom name="ur5e//unnamed_geom_14" class="ur5e/visual" material="ur5e/black" mesh="ur5e/forearm_2"/>
              <geom name="ur5e//unnamed_geom_15" class="ur5e/visual" material="ur5e/jointgray" mesh="ur5e/forearm_3"/>
              <geom name="ur5e//unnamed_geom_16" class="ur5e/collision" size="0.055 0.06" pos="0 0.08 0" quat="0.707107 0.707107 0 0"/>
              <geom name="ur5e//unnamed_geom_17" class="ur5e/collision" size="0.038 0.19" pos="0 0 0.2"/>
              <body name="ur5e/wrist_1_link" pos="0 0 0.392" quat="0.707107 0 0.707107 0">
                <inertial pos="0 0.127 0" mass="1.219" diaginertia="0.0025599 0.0025599 0.0021942"/>
                <joint name="ur5e/wrist_1_joint" class="ur5e/size1" pos="0 0 0" axis="0 1 0"/>
                <geom name="ur5e//unnamed_geom_18" class="ur5e/visual" material="ur5e/black" mesh="ur5e/wrist1_0"/>
                <geom name="ur5e//unnamed_geom_19" class="ur5e/visual" material="ur5e/urblue" mesh="ur5e/wrist1_1"/>
                <geom name="ur5e//unnamed_geom_20" class="ur5e/visual" material="ur5e/jointgray" mesh="ur5e/wrist1_2"/>
                <geom name="ur5e//unnamed_geom_21" class="ur5e/collision" size="0.04 0.07" pos="0 0.05 0" quat="0.707107 0.707107 0 0"/>
                <body name="ur5e/wrist_2_link" pos="0 0.127 0">
                  <inertial pos="0 0 0.1" mass="1.219" diaginertia="0.0025599 0.0025599 0.0021942"/>
                  <joint name="ur5e/wrist_2_joint" class="ur5e/size1" pos="0 0 0" axis="0 0 1"/>
                  <geom name="ur5e//unnamed_geom_22" class="ur5e/visual" material="ur5e/black" mesh="ur5e/wrist2_0"/>
                  <geom name="ur5e//unnamed_geom_23" class="ur5e/visual" material="ur5e/urblue" mesh="ur5e/wrist2_1"/>
                  <geom name="ur5e//unnamed_geom_24" class="ur5e/visual" material="ur5e/jointgray" mesh="ur5e/wrist2_2"/>
                  <geom name="ur5e//unnamed_geom_25" class="ur5e/collision" size="0.04 0.06" pos="0 0 0.04"/>
                  <geom name="ur5e//unnamed_geom_26" class="ur5e/collision" size="0.04 0.04" pos="0 0.02 0.1" quat="0.707107 0.707107 0 0"/>
                  <body name="ur5e/wrist_3_link" pos="0 0 0.1">
                    <inertial pos="0 0.0771683 0" quat="0.707107 0 0 0.707107" mass="0.1889" diaginertia="0.000132134 9.90863e-05 9.90863e-05"/>
                    <joint name="ur5e/wrist_3_joint" class="ur5e/size1" pos="0 0 0" axis="0 1 0"/>
                    <geom name="ur5e//unnamed_geom_27" class="ur5e/visual" material="ur5e/linkgray" mesh="ur5e/wrist3"/>
                    <geom name="ur5e//unnamed_geom_28" class="ur5e/eef_collision" size="0.04 0.02" pos="0 0.08 0" quat="0.707107 0.707107 0 0"/>
                    <site name="ur5e/attachment_site" pos="0 0.1 0" quat="-0.707107 0.707107 0 0"/>
                    <body name="ur5e/robotiq_2f85/" pos="0 0.1 0" quat="-0.707107 0.707107 0 0">
                      <body name="ur5e/robotiq_2f85/base_mount" childclass="ur5e/robotiq_2f85/2f85" pos="0 0 0.007">
                        <geom name="ur5e/robotiq_2f85//unnamed_geom_0" class="ur5e/robotiq_2f85/visual" material="ur5e/robotiq_2f85/black" mesh="ur5e/robotiq_2f85/base_mount"/>
                        <geom name="ur5e/robotiq_2f85//unnamed_geom_1" class="ur5e/robotiq_2f85/collision" mesh="ur5e/robotiq_2f85/base_mount"/>
                        <body name="ur5e/robotiq_2f85/base" pos="0 0 0.0038" quat="0.707107 0 0 -0.707107">
                          <inertial pos="0 -2.70394e-05 0.0354675" quat="0.999999 -0.00152849 0 0" mass="0.777441" diaginertia="0.000260285 0.000225381 0.000152708"/>
                          <geom name="ur5e/robotiq_2f85//unnamed_geom_2" class="ur5e/robotiq_2f85/visual" material="ur5e/robotiq_2f85/black" mesh="ur5e/robotiq_2f85/base"/>
                          <geom name="ur5e/robotiq_2f85//unnamed_geom_3" class="ur5e/robotiq_2f85/collision" mesh="ur5e/robotiq_2f85/base"/>
                          <site name="ur5e/robotiq_2f85/pinch" pos="0 0 0.145" group="5" rgba="0.9 0.9 0.9 1"/>
                          <body name="ur5e/robotiq_2f85/right_driver" pos="0 0.0306011 0.054904">
                            <inertial pos="2.96931e-12 0.0177547 0.00107314" quat="0.681301 0.732003 0 0" mass="0.00899563" diaginertia="1.72352e-06 1.60906e-06 3.22006e-07"/>
                            <joint name="ur5e/robotiq_2f85/right_driver_joint" class="ur5e/robotiq_2f85/driver" pos="0 0 0" axis="1 0 0"/>
                            <geom name="ur5e/robotiq_2f85//unnamed_geom_4" class="ur5e/robotiq_2f85/visual" material="ur5e/robotiq_2f85/gray" mesh="ur5e/robotiq_2f85/driver"/>
                            <geom name="ur5e/robotiq_2f85//unnamed_geom_5" class="ur5e/robotiq_2f85/collision" mesh="ur5e/robotiq_2f85/driver"/>
                            <body name="ur5e/robotiq_2f85/right_coupler" pos="0 0.0315 -0.0041">
                              <inertial pos="0 0.00301209 0.0232175" quat="0.705636 -0.0455904 0.0455904 0.705636" mass="0.0140974" diaginertia="4.16206e-06 3.52216e-06 8.88131e-07"/>
                              <joint name="ur5e/robotiq_2f85/right_coupler_joint" class="ur5e/robotiq_2f85/coupler" pos="0 0 0" axis="1 0 0"/>
                              <geom name="ur5e/robotiq_2f85//unnamed_geom_6" class="ur5e/robotiq_2f85/visual" material="ur5e/robotiq_2f85/black" mesh="ur5e/robotiq_2f85/coupler"/>
                              <geom name="ur5e/robotiq_2f85//unnamed_geom_7" class="ur5e/robotiq_2f85/collision" mesh="ur5e/robotiq_2f85/coupler"/>
                            </body>
                          </body>
                          <body name="ur5e/robotiq_2f85/right_spring_link" pos="0 0.0132 0.0609">
                            <inertial pos="-8.65005e-09 0.0181624 0.0212658" quat="0.663403 -0.244737 0.244737 0.663403" mass="0.0221642" diaginertia="8.96853e-06 6.71733e-06 2.63931e-06"/>
                            <joint name="ur5e/robotiq_2f85/right_spring_link_joint" class="ur5e/robotiq_2f85/spring_link" pos="0 0 0" axis="1 0 0" springref="2.62"/>
                            <geom name="ur5e/robotiq_2f85//unnamed_geom_8" class="ur5e/robotiq_2f85/visual" material="ur5e/robotiq_2f85/black" mesh="ur5e/robotiq_2f85/spring_link"/>
                            <geom name="ur5e/robotiq_2f85//unnamed_geom_9" class="ur5e/robotiq_2f85/collision" mesh="ur5e/robotiq_2f85/spring_link"/>
                            <body name="ur5e/robotiq_2f85/right_follower" pos="0 0.055 0.0375">
                              <inertial pos="0 -0.011046 0.0124786" quat="0.986437 0.164143 0 0" mass="0.0125222" diaginertia="2.67415e-06 2.4559e-06 6.02031e-07"/>
                              <joint name="ur5e/robotiq_2f85/right_follower_joint" class="ur5e/robotiq_2f85/follower" pos="0 -0.018 0.0065" axis="1 0 0"/>
                              <geom name="ur5e/robotiq_2f85//unnamed_geom_10" class="ur5e/robotiq_2f85/visual" material="ur5e/robotiq_2f85/black" mesh="ur5e/robotiq_2f85/follower"/>
                              <geom name="ur5e/robotiq_2f85//unnamed_geom_11" class="ur5e/robotiq_2f85/collision" mesh="ur5e/robotiq_2f85/follower"/>
                              <body name="ur5e/robotiq_2f85/right_pad" pos="0 -0.0189 0.01352">
                                <inertial pos="0 -0.0025 0.0185" quat="0.707107 0 0 0.707107" mass="0.0035" diaginertia="4.73958e-07 3.64583e-07 1.23958e-07"/>
                                <geom name="ur5e/robotiq_2f85/right_pad1" class="ur5e/robotiq_2f85/pad_box1" pos="0 -0.0026 0.028125" mass="0"/>
                                <geom name="ur5e/robotiq_2f85/right_pad2" class="ur5e/robotiq_2f85/pad_box2" pos="0 -0.0026 0.009375" mass="0"/>
                                <geom name="ur5e/robotiq_2f85//unnamed_geom_14" class="ur5e/robotiq_2f85/visual" mesh="ur5e/robotiq_2f85/pad"/>
                                <body name="ur5e/robotiq_2f85/right_silicone_pad">
                                  <geom name="ur5e/robotiq_2f85//unnamed_geom_15" class="ur5e/robotiq_2f85/visual" material="ur5e/robotiq_2f85/black" mesh="ur5e/robotiq_2f85/silicone_pad"/>
                                </body>
                              </body>
                            </body>
                          </body>
                          <body name="ur5e/robotiq_2f85/left_driver" pos="0 -0.0306011 0.054904" quat="0 0 0 1">
                            <inertial pos="0 0.0177547 0.00107314" quat="0.681301 0.732003 0 0" mass="0.00899563" diaginertia="1.72352e-06 1.60906e-06 3.22006e-07"/>
                            <joint name="ur5e/robotiq_2f85/left_driver_joint" class="ur5e/robotiq_2f85/driver" pos="0 0 0" axis="1 0 0"/>
                            <geom name="ur5e/robotiq_2f85//unnamed_geom_16" class="ur5e/robotiq_2f85/visual" material="ur5e/robotiq_2f85/gray" mesh="ur5e/robotiq_2f85/driver"/>
                            <geom name="ur5e/robotiq_2f85//unnamed_geom_17" class="ur5e/robotiq_2f85/collision" mesh="ur5e/robotiq_2f85/driver"/>
                            <body name="ur5e/robotiq_2f85/left_coupler" pos="0 0.0315 -0.0041">
                              <inertial pos="0 0.00301209 0.0232175" quat="0.705636 -0.0455904 0.0455904 0.705636" mass="0.0140974" diaginertia="4.16206e-06 3.52216e-06 8.88131e-07"/>
                              <joint name="ur5e/robotiq_2f85/left_coupler_joint" class="ur5e/robotiq_2f85/coupler" pos="0 0 0" axis="1 0 0"/>
                              <geom name="ur5e/robotiq_2f85//unnamed_geom_18" class="ur5e/robotiq_2f85/visual" material="ur5e/robotiq_2f85/black" mesh="ur5e/robotiq_2f85/coupler"/>
                              <geom name="ur5e/robotiq_2f85//unnamed_geom_19" class="ur5e/robotiq_2f85/collision" mesh="ur5e/robotiq_2f85/coupler"/>
                            </body>
                          </body>
                          <body name="ur5e/robotiq_2f85/left_spring_link" pos="0 -0.0132 0.0609" quat="0 0 0 1">
                            <inertial pos="-8.65005e-09 0.0181624 0.0212658" quat="0.663403 -0.244737 0.244737 0.663403" mass="0.0221642" diaginertia="8.96853e-06 6.71733e-06 2.63931e-06"/>
                            <joint name="ur5e/robotiq_2f85/left_spring_link_joint" class="ur5e/robotiq_2f85/spring_link" pos="0 0 0" axis="1 0 0" springref="2.62"/>
                            <geom name="ur5e/robotiq_2f85//unnamed_geom_20" class="ur5e/robotiq_2f85/visual" material="ur5e/robotiq_2f85/black" mesh="ur5e/robotiq_2f85/spring_link"/>
                            <geom name="ur5e/robotiq_2f85//unnamed_geom_21" class="ur5e/robotiq_2f85/collision" mesh="ur5e/robotiq_2f85/spring_link"/>
                            <body name="ur5e/robotiq_2f85/left_follower" pos="0 0.055 0.0375">
                              <inertial pos="0 -0.011046 0.0124786" quat="0.986437 0.164143 0 0" mass="0.0125222" diaginertia="2.67415e-06 2.4559e-06 6.02031e-07"/>
                              <joint name="ur5e/robotiq_2f85/left_follower_joint" class="ur5e/robotiq_2f85/follower" pos="0 -0.018 0.0065" axis="1 0 0"/>
                              <geom name="ur5e/robotiq_2f85//unnamed_geom_22" class="ur5e/robotiq_2f85/visual" material="ur5e/robotiq_2f85/black" mesh="ur5e/robotiq_2f85/follower"/>
                              <geom name="ur5e/robotiq_2f85//unnamed_geom_23" class="ur5e/robotiq_2f85/collision" mesh="ur5e/robotiq_2f85/follower"/>
                              <body name="ur5e/robotiq_2f85/left_pad" pos="0 -0.0189 0.01352">
                                <inertial pos="0 -0.0025 0.0185" quat="0.707107 0 0 0.707107" mass="0.0035" diaginertia="4.73958e-07 3.64583e-07 1.23958e-07"/>
                                <geom name="ur5e/robotiq_2f85/left_pad1" class="ur5e/robotiq_2f85/pad_box1" pos="0 -0.0026 0.028125" mass="0"/>
                                <geom name="ur5e/robotiq_2f85/left_pad2" class="ur5e/robotiq_2f85/pad_box2" pos="0 -0.0026 0.009375" mass="0"/>
                                <geom name="ur5e/robotiq_2f85//unnamed_geom_26" class="ur5e/robotiq_2f85/visual" mesh="ur5e/robotiq_2f85/pad"/>
                                <body name="ur5e/robotiq_2f85/left_silicone_pad">
                                  <geom name="ur5e/robotiq_2f85//unnamed_geom_27" class="ur5e/robotiq_2f85/visual" material="ur5e/robotiq_2f85/black" mesh="ur5e/robotiq_2f85/silicone_pad"/>
                                </body>
                              </body>
                            </body>
                          </body>
                        </body>
                      </body>
                    </body>
                  </body>
                </body>
              </body>
            </body>
          </body>
        </body>
      </body>
    </body>
    <body name="cube" pos="0 0 0.6">
      <inertial pos="0 0 0" mass="0.1" diaginertia="0.001 0.001 0.001"/>
      <geom name="//unnamed_geom_1" class="/" size="0.1 0.1 0.1" type="box" friction="0.5 0.5 0.5" rgba="1 0 0 1"/>
    </body>
  </worldbody>
  <contact>
    <exclude name="ur5e/robotiq_2f85//unnamed_contact_1" body1="ur5e/robotiq_2f85/base" body2="ur5e/robotiq_2f85/right_driver"/>
    <exclude name="ur5e/robotiq_2f85//unnamed_contact_3" body1="ur5e/robotiq_2f85/base" body2="ur5e/robotiq_2f85/right_spring_link"/>
    <exclude name="ur5e/robotiq_2f85//unnamed_contact_0" body1="ur5e/robotiq_2f85/base" body2="ur5e/robotiq_2f85/left_driver"/>
    <exclude name="ur5e/robotiq_2f85//unnamed_contact_2" body1="ur5e/robotiq_2f85/base" body2="ur5e/robotiq_2f85/left_spring_link"/>
    <exclude name="ur5e/robotiq_2f85//unnamed_contact_4" body1="ur5e/robotiq_2f85/right_coupler" body2="ur5e/robotiq_2f85/right_follower"/>
    <exclude name="ur5e/robotiq_2f85//unnamed_contact_5" body1="ur5e/robotiq_2f85/left_coupler" body2="ur5e/robotiq_2f85/left_follower"/>
  </contact>
  <equality>
    <connect name="ur5e/robotiq_2f85//unnamed_equality_0" class="ur5e/robotiq_2f85/" body1="ur5e/robotiq_2f85/right_follower" body2="ur5e/robotiq_2f85/right_coupler" anchor="0 0 0" solref="0.005 1" solimp="0.95 0.99 0.001 0.5 2"/>
    <connect name="ur5e/robotiq_2f85//unnamed_equality_1" class="ur5e/robotiq_2f85/" body1="ur5e/robotiq_2f85/left_follower" body2="ur5e/robotiq_2f85/left_coupler" anchor="0 0 0" solref="0.005 1" solimp="0.95 0.99 0.001 0.5 2"/>
    <joint name="ur5e/robotiq_2f85//unnamed_equality_2" class="ur5e/robotiq_2f85/" joint1="ur5e/robotiq_2f85/right_driver_joint" joint2="ur5e/robotiq_2f85/left_driver_joint" polycoef="0 1 0 0 0" solref="0.005 1" solimp="0.95 0.99 0.001 0.5 2"/>
  </equality>
  <tendon>
    <fixed name="ur5e/robotiq_2f85/split" class="ur5e/robotiq_2f85/">
      <joint joint="ur5e/robotiq_2f85/right_driver_joint" coef="0.5"/>
      <joint joint="ur5e/robotiq_2f85/left_driver_joint" coef="0.5"/>
    </fixed>
  </tendon>
  <actuator>
    <general name="ur5e/shoulder_pan" class="ur5e/size3" joint="ur5e/shoulder_pan_joint"/>
    <general name="ur5e/shoulder_lift" class="ur5e/size3" joint="ur5e/shoulder_lift_joint"/>
    <general name="ur5e/elbow" class="ur5e/size3_limited" joint="ur5e/elbow_joint"/>
    <general name="ur5e/wrist_1" class="ur5e/size1" joint="ur5e/wrist_1_joint"/>
    <general name="ur5e/wrist_2" class="ur5e/size1" joint="ur5e/wrist_2_joint"/>
    <general name="ur5e/wrist_3" class="ur5e/size1" joint="ur5e/wrist_3_joint"/>
    <general name="ur5e/robotiq_2f85/fingers_actuator" class="ur5e/robotiq_2f85/2f85" tendon="ur5e/robotiq_2f85/split" ctrlrange="0 255" forcerange="-5 5" gainprm="0.313725 0 0 0 0 0 0 0 0 0" biasprm="0 -100 -10 0 0 0 0 0 0 0"/>
  </actuator>
  <keyframe>
    <key name="ur5e/home" qpos="-1.5708 -1.5708 1.5708 -1.5708 -1.5708 0 0 0 0 0 0 0 0 0" ctrl="-1.5708 -1.5708 1.5708 -1.5708 -1.5708 0 0"/>
  </keyframe>
</mujoco>
