<?xml version="1.0" ?>
<robot name="partnet_32b136a0c50f117d365f49f10cc5bd41">
	<link name="base"/>
	<link name="link_0">
		<visual name="leg-1">
			<origin xyz="0.6515797226901525 -0.09790684229950442 -0.16440800966958607"/>
			<geometry>
				<mesh filename="textured_objs/original-3.obj"/>
			</geometry>
		</visual>
		<collision>
			<origin xyz="0.6515797226901525 -0.09790684229950442 -0.16440800966958607"/>
			<geometry>
				<mesh filename="textured_objs/original-3.obj"/>
			</geometry>
		</collision>
	</link>
	<joint name="joint_0" type="revolute">
		<origin xyz="-0.6515797226901525 0.09790684229950442 0.16440800966958607"/>
		<axis xyz="0 -1 0"/>
		<child link="link_0"/>
		<parent link="link_2"/>
		<limit lower="-0.0" upper="1.1623892818282238"/>
	</joint>
	<link name="link_1">
		<visual name="leg-2">
			<origin xyz="-0.6316526308559023 -0.09926066379861531 -0.1680707768901497"/>
			<geometry>
				<mesh filename="textured_objs/original-2.obj"/>
			</geometry>
		</visual>
		<collision>
			<origin xyz="-0.6316526308559023 -0.09926066379861531 -0.1680707768901497"/>
			<geometry>
				<mesh filename="textured_objs/original-2.obj"/>
			</geometry>
		</collision>
	</link>
	<joint name="joint_1" type="revolute">
		<origin xyz="0.6316526308559023 0.09926066379861531 0.1680707768901497"/>
		<axis xyz="0 1 0"/>
		<child link="link_1"/>
		<parent link="link_2"/>
		<limit lower="0.0" upper="1.501681288415921"/>
	</joint>
	<link name="link_2">
		<visual name="base_body-3">
			<origin xyz="0 0 0"/>
			<geometry>
				<mesh filename="textured_objs/original-1.obj"/>
			</geometry>
		</visual>
		<collision>
			<origin xyz="0 0 0"/>
			<geometry>
				<mesh filename="textured_objs/original-1.obj"/>
			</geometry>
		</collision>
	</link>
	<joint name="joint_2" type="fixed">
		<origin rpy="1.570796326794897 0 -1.570796326794897" xyz="0 0 0"/>
		<child link="link_2"/>
		<parent link="base"/>
	</joint>
</robot>
